Traceback (most recent call last):
  File "/usr/share/miniconda/envs/microdf/lib/python3.7/site-packages/jupyter_cache/executors/utils.py", line 56, in single_nb_execution
    record_timing=False,
  File "/usr/share/miniconda/envs/microdf/lib/python3.7/site-packages/nbclient/client.py", line 1082, in execute
    return NotebookClient(nb=nb, resources=resources, km=km, **kwargs).execute()
  File "/usr/share/miniconda/envs/microdf/lib/python3.7/site-packages/nbclient/util.py", line 74, in wrapped
    return just_run(coro(*args, **kwargs))
  File "/usr/share/miniconda/envs/microdf/lib/python3.7/site-packages/nbclient/util.py", line 53, in just_run
    return loop.run_until_complete(coro)
  File "/usr/share/miniconda/envs/microdf/lib/python3.7/asyncio/base_events.py", line 587, in run_until_complete
    return future.result()
  File "/usr/share/miniconda/envs/microdf/lib/python3.7/site-packages/nbclient/client.py", line 536, in async_execute
    cell, index, execution_count=self.code_cells_executed + 1
  File "/usr/share/miniconda/envs/microdf/lib/python3.7/site-packages/nbclient/client.py", line 827, in async_execute_cell
    self._check_raise_for_error(cell, exec_reply)
  File "/usr/share/miniconda/envs/microdf/lib/python3.7/site-packages/nbclient/client.py", line 735, in _check_raise_for_error
    raise CellExecutionError.from_cell_and_msg(cell, exec_reply['content'])
nbclient.exceptions.CellExecutionError: An error occurred while executing the following cell:
------------------
mdf.gini(pd.DataFrame({'x': [0, 0, 0, 5, 100]}))
------------------

[0;31m---------------------------------------------------------------------------[0m
[0;31mTypeError[0m                                 Traceback (most recent call last)
[0;32m<ipython-input-5-af8155089122>[0m in [0;36m<module>[0;34m[0m
[0;32m----> 1[0;31m [0mmdf[0m[0;34m.[0m[0mgini[0m[0;34m([0m[0mpd[0m[0;34m.[0m[0mDataFrame[0m[0;34m([0m[0;34m{[0m[0;34m'x'[0m[0;34m:[0m [0;34m[[0m[0;36m0[0m[0;34m,[0m [0;36m0[0m[0;34m,[0m [0;36m0[0m[0;34m,[0m [0;36m5[0m[0;34m,[0m [0;36m100[0m[0;34m][0m[0;34m}[0m[0;34m)[0m[0;34m)[0m[0;34m[0m[0;34m[0m[0m
[0m
[0;31mTypeError[0m: gini() missing 1 required positional argument: 'col'
TypeError: gini() missing 1 required positional argument: 'col'

